2020-09-22 10:58:26,165 - ERROR: 扫描设备线程异常:
Traceback (most recent call last):
  File "E:\Program Files\miniconda3\lib\site-packages\ppadb\connection.py", line 36, in connect
    self.socket.connect((self.host, self.port))
ConnectionRefusedError: [WinError 10061] 由于目标计算机积极拒绝，无法连接。

During handling of the above exception, another exception occurred:

Traceback (most recent call last):
  File "E:\SelfWork\python\ADBcontroller\service\ScanDeviceThread.py", line 31, in run
    deviceList = client.devices()
  File "E:\Program Files\miniconda3\lib\site-packages\ppadb\command\host\__init__.py", line 23, in devices
    result = self._execute_cmd(cmd)
  File "E:\Program Files\miniconda3\lib\site-packages\ppadb\command\host\__init__.py", line 13, in _execute_cmd
    with self.create_connection() as conn:
  File "E:\Program Files\miniconda3\lib\site-packages\ppadb\client.py", line 14, in create_connection
    conn.connect()
  File "E:\Program Files\miniconda3\lib\site-packages\ppadb\connection.py", line 39, in connect
    raise RuntimeError("ERROR: connecting to {}:{} {}.\nIs adb running on your computer?".format(
RuntimeError: ERROR: connecting to 127.0.0.1:5037 [WinError 10061] 由于目标计算机积极拒绝，无法连接。.
Is adb running on your computer?
2020-09-22 10:59:54,639 - ERROR: 扫描设备线程异常:
Traceback (most recent call last):
  File "E:\Program Files\miniconda3\lib\site-packages\ppadb\connection.py", line 36, in connect
    self.socket.connect((self.host, self.port))
ConnectionRefusedError: [WinError 10061] 由于目标计算机积极拒绝，无法连接。

During handling of the above exception, another exception occurred:

Traceback (most recent call last):
  File "E:\SelfWork\python\ADBcontroller\service\ScanDeviceThread.py", line 31, in run
    deviceList = client.devices()
  File "E:\Program Files\miniconda3\lib\site-packages\ppadb\command\host\__init__.py", line 23, in devices
    result = self._execute_cmd(cmd)
  File "E:\Program Files\miniconda3\lib\site-packages\ppadb\command\host\__init__.py", line 13, in _execute_cmd
    with self.create_connection() as conn:
  File "E:\Program Files\miniconda3\lib\site-packages\ppadb\client.py", line 14, in create_connection
    conn.connect()
  File "E:\Program Files\miniconda3\lib\site-packages\ppadb\connection.py", line 39, in connect
    raise RuntimeError("ERROR: connecting to {}:{} {}.\nIs adb running on your computer?".format(
RuntimeError: ERROR: connecting to 127.0.0.1:5037 [WinError 10061] 由于目标计算机积极拒绝，无法连接。.
Is adb running on your computer?
2020-09-22 11:00:52,765 - ERROR: 扫描设备线程异常:
Traceback (most recent call last):
  File "E:\Program Files\miniconda3\lib\site-packages\ppadb\connection.py", line 36, in connect
    self.socket.connect((self.host, self.port))
ConnectionRefusedError: [WinError 10061] 由于目标计算机积极拒绝，无法连接。

During handling of the above exception, another exception occurred:

Traceback (most recent call last):
  File "E:\SelfWork\python\ADBcontroller\service\ScanDeviceThread.py", line 31, in run
    deviceList = client.devices()
  File "E:\Program Files\miniconda3\lib\site-packages\ppadb\command\host\__init__.py", line 23, in devices
    result = self._execute_cmd(cmd)
  File "E:\Program Files\miniconda3\lib\site-packages\ppadb\command\host\__init__.py", line 13, in _execute_cmd
    with self.create_connection() as conn:
  File "E:\Program Files\miniconda3\lib\site-packages\ppadb\client.py", line 14, in create_connection
    conn.connect()
  File "E:\Program Files\miniconda3\lib\site-packages\ppadb\connection.py", line 39, in connect
    raise RuntimeError("ERROR: connecting to {}:{} {}.\nIs adb running on your computer?".format(
RuntimeError: ERROR: connecting to 127.0.0.1:5037 [WinError 10061] 由于目标计算机积极拒绝，无法连接。.
Is adb running on your computer?
2020-09-22 11:17:52,630 - ERROR: 扫描设备线程异常:
Traceback (most recent call last):
  File "E:\Program Files\miniconda3\lib\site-packages\ppadb\connection.py", line 36, in connect
    self.socket.connect((self.host, self.port))
ConnectionRefusedError: [WinError 10061] 由于目标计算机积极拒绝，无法连接。

During handling of the above exception, another exception occurred:

Traceback (most recent call last):
  File "E:\SelfWork\python\ADBcontroller\service\ScanDeviceThread.py", line 31, in run
    deviceList = client.devices()
  File "E:\Program Files\miniconda3\lib\site-packages\ppadb\command\host\__init__.py", line 23, in devices
    result = self._execute_cmd(cmd)
  File "E:\Program Files\miniconda3\lib\site-packages\ppadb\command\host\__init__.py", line 13, in _execute_cmd
    with self.create_connection() as conn:
  File "E:\Program Files\miniconda3\lib\site-packages\ppadb\client.py", line 14, in create_connection
    conn.connect()
  File "E:\Program Files\miniconda3\lib\site-packages\ppadb\connection.py", line 39, in connect
    raise RuntimeError("ERROR: connecting to {}:{} {}.\nIs adb running on your computer?".format(
RuntimeError: ERROR: connecting to 127.0.0.1:5037 [WinError 10061] 由于目标计算机积极拒绝，无法连接。.
Is adb running on your computer?
2020-09-22 11:18:41,556 - ERROR: 扫描设备线程异常:
Traceback (most recent call last):
  File "E:\Program Files\miniconda3\lib\site-packages\ppadb\connection.py", line 36, in connect
    self.socket.connect((self.host, self.port))
ConnectionRefusedError: [WinError 10061] 由于目标计算机积极拒绝，无法连接。

During handling of the above exception, another exception occurred:

Traceback (most recent call last):
  File "E:\SelfWork\python\ADBcontroller\service\ScanDeviceThread.py", line 31, in run
    deviceList = client.devices()
  File "E:\Program Files\miniconda3\lib\site-packages\ppadb\command\host\__init__.py", line 23, in devices
    result = self._execute_cmd(cmd)
  File "E:\Program Files\miniconda3\lib\site-packages\ppadb\command\host\__init__.py", line 13, in _execute_cmd
    with self.create_connection() as conn:
  File "E:\Program Files\miniconda3\lib\site-packages\ppadb\client.py", line 14, in create_connection
    conn.connect()
  File "E:\Program Files\miniconda3\lib\site-packages\ppadb\connection.py", line 39, in connect
    raise RuntimeError("ERROR: connecting to {}:{} {}.\nIs adb running on your computer?".format(
RuntimeError: ERROR: connecting to 127.0.0.1:5037 [WinError 10061] 由于目标计算机积极拒绝，无法连接。.
Is adb running on your computer?
2020-09-22 18:11:14,025 - ERROR: 删除文件异常:
Traceback (most recent call last):
  File "E:\SelfWork\python\ADBcontroller\ui\ChooseConfigWindow.py", line 148, in removeFile
    os.remove(filePath)
PermissionError: [WinError 5] 拒绝访问。: './db/123'
2020-09-22 18:12:01,458 - ERROR: 删除文件异常:
Traceback (most recent call last):
  File "E:\SelfWork\python\ADBcontroller\ui\ChooseConfigWindow.py", line 148, in removeFile
    os.remove(filePath)
PermissionError: [WinError 5] 拒绝访问。: './db/123'
2020-09-22 18:13:13,858 - ERROR: 删除文件异常:
Traceback (most recent call last):
  File "E:\SelfWork\python\ADBcontroller\ui\ChooseConfigWindow.py", line 149, in removeFile
    shutil.rmtree(folder)
  File "E:\Program Files\miniconda3\lib\shutil.py", line 730, in rmtree
    if _rmtree_islink(path):
  File "E:\Program Files\miniconda3\lib\shutil.py", line 574, in _rmtree_islink
    st = os.lstat(path)
TypeError: lstat: path should be string, bytes or os.PathLike, not bool
2020-09-22 18:16:00,422 - ERROR: 删除文件异常:
Traceback (most recent call last):
  File "E:\SelfWork\python\ADBcontroller\ui\ChooseConfigWindow.py", line 149, in removeFile
    os.remove(filePath)
PermissionError: [WinError 5] 拒绝访问。: './db/123'
2020-09-22 18:16:40,832 - ERROR: 删除文件异常:
Traceback (most recent call last):
  File "E:\SelfWork\python\ADBcontroller\ui\ChooseConfigWindow.py", line 149, in removeFile
    os.remove(filePath)
PermissionError: [WinError 5] 拒绝访问。: './db/13123'
